Workbook

Sheet PA Metrics Site
D7: Safety Train P/D | H7: LOC Count | L7: Site Wide 2026 Business Plan Targets | Y7: Property Damages | AC7: Safety WO P/D
H8: 1 | Y8: 1
L9: Metric | N9: Week Ending 3/1/26 | P9: Month / Mar. | R9: Year To Date | T9: BP Target (E+C) | V9: Actual (E+C)
E10: 800 | F10: - | I10: 9 | J10: - | Z10: 9 | AA10: - | AD10: 45 | AE10: -
E11: 750 | F11: - | I11: 8 | J11: - | Z11: 8 | AA11: - | AD11: 40 | AE11: -
E12: 650 | F12: - | I12: 7 | J12: - | N12: Own | O12: Contract | P12: Own | Q12: Contract | R12: Own | S12: Contract | T12: 2026 | V12: YTD | Z12: 7 | AA12: - | AD12: 35 | AE12: -
E13: 550 | F13: - | I13: 6 | J13: - | L13: LTI | N13: 0 | O13: 0 | P13: 0 | Q13: 0 | R13: 0 | S13: 0 | T13: 0 | V13: =Rates!E42 -> 1 | Z13: 6 | AA13: - | AD13: 30 | AE13: -
E14: 450 | F14: - | I14: 5 | J14: - | Z14: 5 | AA14: - | AD14: 25 | AE14: -
E15: 350 | F15: - | I15: 4 | J15: - | Z15: 4 | AA15: - | AD15: 20 | AE15: -
E16: 250 | F16: - | I16: 3 | J16: - | L16: Recordable | N16: 0 | O16: 0 | P16: 0 | Q16: 0 | R16: 0 | S16: 0 | T16: 0 | V16: =Rates!F42 -> 1 | Z16: 3 | AA16: - | AD16: 15 | AE16: -
E17: 150 | F17: - | I17: 2 | J17: - | Z17: 2 | AA17: - | AD17: 10 | AE17: -
E18: 50 | F18: - | I18: 1 | J18: - | Z18: 1 | AA18: - | AD18: 5 | AE18: -
D19: KPI | E19: 0 | F19: - | H19: KPI | I19: 0 | J19: - | L19: First Aid | N19: 0 | O19: 0 | P19: 0 | Q19: 0 | R19: 1 | S19: 0 | T19: 0 | V19: =Rates!G42 -> 4 | Y19: KPI | Z19: 0 | AA19: - | AC19: KPI | AD19: 0 | AE19: -
E20: Target | I20: Target | Z20: Target | AD20: Target
L22: Fire | N22: 0 | O22: 0 | P22: 0 | Q22: 0 | R22: 0 | S22: 0 | T22: 5 | V22: =R22 -> 0
D25: Past Due CA | H25: Open Investigations | L25: Property/ Equipment Damages | N25: 0 | O25: 0 | P25: 0 | Q25: 0 | R25: 1 | S25: 0 | T25: 10 | V25: =R25 -> 1 | Y25: PSIF Frequency | AC25: Near Miss Month
H26: 2 | Y26: 1 | AC26: 2
E28: 225 | F28: - | I28: 225 | J28: - | L28: LOPC | N28: 1 | O28: 0 | P28: 0 | Q28: 0 | R28: 3 | S28: 0 | T28: 11 | V28: =R28 -> 3 | Z28: 9 | AA28: - | AD28: 45 | AE28: -
E29: 200 | F29: - | I29: 200 | J29: - | Z29: 8 | AA29: - | AD29: 40 | AE29: -
E30: 175 | F30: - | I30: 175 | J30: - | Z30: 7 | AA30: - | AD30: 35 | AE30: -
E31: 150 | F31: - | I31: 150 | J31: - | L31: PSIF | N31: 0 | O31: 0 | P31: 0 | Q31: 0 | R31: 2 | S31: 0 | T31: 3 | V31: =R31 -> 2 | Z31: 6 | AA31: - | AD31: 30 | AE31: -
E32: 125 | F32: - | I32: 125 | J32: - | Z32: 5 | AA32: - | AD32: 25 | AE32: -
E33: 100 | F33: - | I33: 100 | J33: - | Z33: 4 | AA33: - | AD33: 20 | AE33: -
E34: 75 | F34: - | I34: 75 | J34: - | Z34: 3 | AA34: - | AD34: 15 | AE34: -
E35: 50 | F35: - | I35: 50 | J35: - | Z35: 2 | AA35: - | AD35: 10 | AE35: -
E36: 25 | F36: - | I36: 25 | J36: - | L36: LCY Risk Indication | Z36: 1 | AA36: - | AD36: 5 | AE36: -
D37: KPI | E37: 0 | F37: - | H37: KPI | I37: 0 | J37: - | Y37: KPI | Z37: 0 | AA37: - | AC37: KPI | AD37: 0 | AE37: -
E38: Target | I38: Target | L38: Overall KPI Indication | V38: Performance Level | Z38: Target | AD38: Target

Sheet Rates
D1: LCY ELASTOMERS LP - Baytown OH&S PERFORMANCE RATES
C4: YR | D4: Month | E4: LTI | F4: Number of Recordable Injuries | G4: Number of First Aids | H4: Number 0f LOC | I4: Number of Equipment Failure | J4: Number of Property Damage | K4: Monthly Hours Worked (Hourly) | L4: Monthly Hours Worked (Salary) | M4: Monthly Hours Worked (Total) | N4: 12-Month Rolling | O4: TRIR Calc | P4: First aid Rate | Q4: LOC Rate | R4: Equip. Rate | S4: Property damage rate
C5: 2022 | D5: Jan | E5: 0 | F5: 0 | G5: 0 | H5: 2 | J5: 2 | K5: 21429.25 | L5: 13144 | M5: =SUM(K5:L5) -> 34573.25 | N5: =M5 -> 34573.25 | O5: =F5*200000/N5 -> 0 | P5: =G5*200000/N5 -> 0 | Q5: =H5*200000/M5 -> 11.569638 | S5: =J5*200000/M5 -> 11.569638 | U5: Recordable | V5: 1 | W5: 3 | X5: 1 | Y5: 1 | Z5: 0 | AA5: 0
C6: 2022 | D6: Feb | E6: 0 | F6: 0 | G6: 0 | H6: 9 | J6: 6 | K6: 20979.5 | L6: 13144 | M6: =SUM(K6:L6) -> 34123.5 | N6: =SUM(M5:M6) -> 68696.75 | O6: =F6*200000/N6 -> 0 | P6: =G6*200000/N6 -> 0 | Q6: =H6*200000/M6 -> 52.749571 | S6: =J6*200000/M6 -> 35.166381
C7: 2022 | D7: Mar | E7: 0 | F7: 0 | G7: 0 | H7: 7 | J7: 4 | K7: 23804.5 | L7: 13144 | M7: =SUM(K7:L7) -> 36948.5 | N7: =SUM(M5:M7) -> 105645.25 | O7: =F7*200000/N7 -> 0 | P7: =G7*200000/N7 -> 0 | Q7: =H7*200000/M7 -> 37.890577 | S7: =J7*200000/M7 -> 21.651759
C8: 2022 | D8: Apr | E8: 0 | F8: 0 | G8: 0 | H8: 9 | J8: 5 | K8: 22352.3 | L8: 13144 | M8: =SUM(K8:L8) -> 35496.3 | N8: =SUM(M5:M8) -> 141141.55 | O8: =F8*200000/N8 -> 0 | P8: =G8*200000/N8 -> 0 | Q8: =H8*200000/M8 -> 50.709511 | S8: =J8*200000/M8 -> 28.17195
C9: 2022 | D9: May | E9: 0 | F9: 0 | G9: 0 | H9: 17 | J9: 5 | K9: 21748.25 | L9: 13144 | M9: =SUM(K9:L9) -> 34892.25 | N9: =SUM(M5:M9) -> 176033.8 | O9: =F9*200000/N9 -> 0 | P9: =G9*200000/N9 -> 0 | Q9: =H9*200000/M9 -> 97.442842 | S9: =J9*200000/M9 -> 28.659659
C10: 2022 | D10: Jun | E10: 0 | F10: 0 | G10: 1 | H10: 15 | J10: 1 | K10: 21426.75 | L10: 13144 | M10: =SUM(K10:L10) -> 34570.75 | N10: =SUM(M5:M10) -> 210604.55 | O10: =F10*200000/N10 -> 0 | P10: =G10*200000/N10 -> 0.9496471 | Q10: =H10*200000/M10 -> 86.778563 | S10: =J10*200000/M10 -> 5.7852375
C11: 2022 | D11: Jul | E11: 0 | F11: 0 | G11: 0 | H11: 9 | J11: 1 | K11: 21953.25 | L11: 13144 | M11: =SUM(K11:L11) -> 35097.25 | N11: =SUM(M5:M11) -> 245701.8 | O11: =F11*200000/N11 -> 0 | P11: =G11*200000/N11 -> 0 | Q11: =H11*200000/M11 -> 51.286069 | S11: =J11*200000/M11 -> 5.6984522
C12: 2022 | D12: Aug | E12: 0 | F12: 0 | G12: 0 | H12: 4 | J12: 3 | K12: 22836.5 | L12: 13144 | M12: =SUM(K12:L12) -> 35980.5 | N12: =SUM(M5:M12) -> 281682.3 | O12: =F12*200000/N12 -> 0 | P12: =G12*200000/N12 -> 0 | Q12: =H12*200000/M12 -> 22.234266 | S12: =J12*200000/M12 -> 16.675699 | U12: Man Hours | V12: 172301 | W12: 176350 | X12: 168563 | Y12: 174706 | Z12: 191751 | AA12: =Rates!AA39 -> 0
C13: 2022 | D13: Sep | E13: 0 | F13: 0 | G13: 0 | H13: 10 | J13: 0 | K13: 22411.75 | L13: 13144 | M13: =SUM(K13:L13) -> 35555.75 | N13: =SUM(M5:M13) -> 317238.05 | O13: =F13*200000/N13 -> 0 | P13: =G13*200000/N13 -> 0 | Q13: =H13*200000/M13 -> 56.249692 | S13: =J13*200000/M13 -> 0
C14: 2022 | D14: Oct | E14: 0 | F14: 0 | G14: 0 | H14: 6 | J14: 2 | K14: 22252.3 | L14: 13144 | M14: =SUM(K14:L14) -> 35396.3 | N14: =SUM(M5:M14) -> 352634.35 | O14: =F14*200000/N14 -> 0 | P14: =G14*200000/N14 -> 0 | Q14: =H14*200000/M14 -> 33.901848 | S14: =J14*200000/M14 -> 11.300616 | U14: LCY TRIR | V14: 1.16 | W14: 3.4 | X14: 1.19 | Y14: 1.14 | Z14: =Z5*200000/Z12 -> 0 | AA14: =AA5*200000/AA12 -> #DIV/0!
C15: 2022 | D15: Nov | E15: 0 | F15: 0 | G15: 0 | H15: 8 | J15: 1 | K15: 22925.3 | L15: 13144 | M15: =SUM(K15:L15) -> 36069.3 | N15: =SUM(M5:M15) -> 388703.65 | O15: =F15*200000/N15 -> 0 | P15: =G15*200000/N15 -> 0 | Q15: =H15*200000/M15 -> 44.359053 | S15: =J15*200000/M15 -> 5.5448817 | U15: Bureau of labor Statistics industry avg. | V15: 2.7 | W15: 1.9 | X15: 1.9 | Y15: 1.9 | Z15: 1.9 | AA15: 1.9
C16: 2022 | D16: Dec | E16: 0 | F16: 0 | G16: 0 | H16: 2 | J16: 1 | K16: 23192.25 | L16: 13144 | M16: =SUM(K16:L16) -> 36336.25 | N16: =SUM(M5:M16) -> 425039.9 | O16: =F16*200000/N16 -> 0 | P16: =G16*200000/N16 -> 0 | Q16: =H16*200000/M16 -> 11.008291 | S16: =J16*200000/M16 -> 5.5041453 | V16: =V10*200000/V12 -> 0 | W16: =W10*200000/W12 -> 0 | X16: =X10*200000/X12 -> 0 | Y16: =Y10*200000/Y12 -> 0 | Z16: =Z5*200000/Z12 -> 0
C17: 2025 | D17: Jan | H17: 3 | J17: 2 | M17: 15000 | N17: =+SUM(M17) -> 15000 | O17: =F41*200000/N17 -> 13.333333 | P17: =G17*200000/N17 -> 0 | Q17: =H17*200000/N17 -> 40 | S17: =J17*200000/M17 -> 26.666667
C18: 2025 | D18: Feb | M18: 15941 | N18: =SUM(M17:M18) -> 30941 | O18: =F41*200000/N18 -> 6.4639152 | P18: =G18*200000/N18 -> 0 | Q18: =H18*200000/N18 -> 0 | S18: =J18*200000/M18 -> 0
C19: 2025 | D19: Mar | G19: 1 | H19: 1 | J19: 2 | M19: 15785 | N19: =SUM(M17:M19) -> 46726 | O19: =F42*200000/N19 -> 4.2802722 | P19: =G19*200000/N19 -> 4.2802722 | Q19: =H19*200000/N19 -> 4.2802722 | S19: =J19*200000/M19 -> 25.340513
C20: 2025 | D20: Apr | G20: 2 | H20: 1 | J20: 1 | M20: 16858 | N20: =SUM(M17:M20) -> 63584 | O20: =F42*200000/N20 -> 3.1454454 | P20: =G20*200000/N20 -> 6.2908908 | Q20: =H20*200000/N20 -> 3.1454454 | S20: =J20*200000/M20 -> 11.863804
C21: 2025 | D21: May | H21: 1 | J21: 1 | M21: 17091 | N21: =SUM(M17:M21) -> 80675 | O21: =F42*200000/N21 -> 2.4790827 | P21: =G21*200000/N21 -> 0 | Q21: =H21*200000/N21 -> 2.4790827 | S21: =J21*200000/M21 -> 11.702065
C22: 2025 | D22: Jun | G22: 1 | H22: 1 | J22: 1 | M22: 15833 | N22: =SUM(M17:M22) -> 96508 | O22: =F42*200000/N22 -> 2.0723671 | P22: =G22*200000/N22 -> 2.0723671 | Q22: =H22*200000/N22 -> 2.0723671 | S22: =J22*200000/M22 -> 12.631845
C23: 2025 | D23: Jul | G23: 1 | H23: 1 | J23: 3 | M23: 14706 | N23: =SUM(M17:M23) -> 111214 | O23: =F41*200000/N23 -> 1.7983347 | P23: =G23*200000/N23 -> 1.7983347 | Q23: =H23*200000/N23 -> 1.7983347 | S23: =J23*200000/M23 -> 40.799674
C24: 2025 | D24: Aug | G24: 1 | H24: 1 | J24: 2 | M24: 15097 | N24: =SUM(M17:M24) -> 126311 | O24: =F42*200000/N24 -> 1.5833934 | P24: =G24*200000/N24 -> 1.5833934 | Q24: =H24*200000/N24 -> 1.5833934 | S24: =J24*200000/M24 -> 26.49533
C25: 2025 | D25: Sep | H25: 2 | J25: 1 | M25: 16918 | N25: =SUM(M17:M25) -> 143229 | O25: =F43*200000/N25 -> 0 | P25: =G25*200000/N25 -> 0 | Q25: =H25*200000/N25 -> 2.7927305 | S25: =J25*200000/M25 -> 11.821728
C26: 2025 | D26: Oct | G26: 1 | H26: 1 | M26: 16632 | N26: =SUM(M17:M26) -> 159861 | O26: =F44*200000/N26 -> 0 | P26: =G26*200000/N26 -> 1.2510869 | Q26: =H26*200000/N26 -> 1.2510869 | S26: =J26*200000/M26 -> 0
C27: 2025 | D27: Nov | J27: 1 | M27: 15591 | N27: =SUM(M17:M27) -> 175452 | O27: =F45*200000/N27 -> 0 | P27: =G27*200000/N27 -> 0 | Q27: =H27*200000/N27 -> 0 | S27: =J27*200000/M27 -> 12.827914
C28: 2025 | D28: Dec | E28: 0 | F28: 0 | G28: 0 | H28: 1 | I28: 1 | J28: 0 | M28: 16299 | N28: =SUM(M17:M28) -> 191751 | O28: =F46*200000/N28 -> 0 | P28: =G28*200000/N28 -> 0 | Q28: =H28*200000/N28 -> 1.0430193 | S28: =J28*200000/M28 -> 0
C29: 2026 | D29: Jan | E29: 0 | F29: 0 | G29: 1 | H29: 1 | I29: 0 | J29: 1 | M29: 21473 | N29: =M29 -> 21473 | O29: =F47*200000/N29 -> 0 | P29: =G29*200000/N29 -> 9.3140223 | Q29: =H29*200000/N29 -> 9.3140223 | S29: =J29*200000/N29 -> 9.3140223
C30: 2026 | D30: Feb | E30: 0 | F30: 0 | G30: 0 | H30: 2 | I30: 0 | J30: 0 | M30: 17654 | N30: =SUM(M29:M30) -> 39127 | O30: =F48*200000/N30 -> 0 | P30: =G30*200000/N30 -> 0 | Q30: =H30*200000/N30 -> 10.22312 | S30: =J30*200000/N30 -> 0
C31: 2026 | D31: Mar | E31: 0 | F31: 0 | G31: 1 | H31: 2 | I31: 1 | J31: 0 | M31: 18698 | N31: =SUM(M29:M31) -> 57825 | O31: =F49*200000/N31 -> 0 | P31: =G31*200000/N31 -> 3.4587116 | Q31: =H31*200000/N31 -> 6.9174233 | S31: =J31*200000/N31 -> 0
C32: 2026 | D32: Apr | E32: 0 | F32: 0 | G32: 2 | H32: 1 | I32: 0 | J32: 3 | M32: 18068 | N32: =SUM(M21:M32) -> 204060 | O32: =F50*200000/N32 -> 0 | P32: =G32*200000/N32 -> 1.9602078 | Q32: =H32*200000/N32 -> 0.98010389 | S32: =J32*200000/N32 -> 2.9403117
C33: 2026 | D33: May | E33: 0 | F33: 0 | G33: 0 | H33: 0 | I33: 0 | J33: 2 | M33: 17366 | N33: =SUM(M22:M33) -> 204335 | O33: =F51*200000/N33 -> 0 | P33: =G33*200000/N33 -> 0 | Q33: =H33*200000/N33 -> 0 | S33: =J33*200000/N33 -> 1.9575697
C34: 2026 | D34: Jun | E34: 0 | F34: 0 | G34: 0 | H34: 2 | I34: 0 | J34: 2 | M34: 17111 | N34: =SUM(M23:M34) -> 205613 | O34: =F52*200000/N34 -> 0 | P34: =G34*200000/N34 -> 0 | Q34: =H34*200000/N34 -> 1.9454023 | S34: =J34*200000/N34 -> 1.9454023
C35: 2026 | D35: Jul | E35: 0 | F35: 0 | G35: 0 | H35: 3 | I35: 0 | J35: 2 | M35: 16793 | N35: =SUM(M24:M35) -> 207700 | O35: =F53*200000/N35 -> 0 | P35: =G35*200000/N35 -> 0 | Q35: =H35*200000/N35 -> 2.8887819 | S35: =J35*200000/N35 -> 1.9258546
C36: 2026 | D36: Aug | E36: 1 | F36: 1 | G36: 0 | H36: 2 | I36: 0 | J36: 0 | M36: 18031 | N36: =SUM(M25:M36) -> 210634 | O36: =F41*200000/N36 -> 0.94951432 | P36: =G36*200000/N36 -> 0 | Q36: =H36*200000/N36 -> 1.8990286 | S36: =J36*200000/N36 -> 0
C37: 2026 | D37: Sep | E37: 0 | F37: 0 | G37: 0 | H37: 1 | I37: 0 | J37: 1
C38: 2026 | D38: Oct
C39: 2026 | D39: Nov
C40: 2026 | D40: Dec
D41: Rolling | E41: =SUM(E21:E37) -> 1 | F41: =SUM(F21:F37) -> 1 | G41: =SUM(G24:G35) -> 6 | H41: =SUM(H24:H35) -> 16 | I41: =SUM(I24:I37) -> 2 | J41: =SUM(J24:J35) -> 14 | M41: =SUM(M25:M36) -> 210634 | N41: 12MRA | V41: 2021 | W41: 2022 | X41: 2023 | Y41: 2024 | Z41: 2025 | AA41: 2026
D42: YTD 26 | E42: =SUM(E29:E40) -> 1 | F42: =SUM(F29:F40) -> 1 | G42: =SUM(G29:G40) -> 4 | H42: =SUM(H29:H40) -> 14 | I42: =SUM(I29:I40) -> 1 | J42: =SUM(J29:J40) -> 11 | M42: =SUM(M29:M40) -> 145194 | N42: YTD | U42: Recordable | V42: 1 | W42: 3 | X42: 1 | Y42: 1 | Z42: 0 | AA42: 2
...

Sheet Dash
O1: 2026 SAFETY DASHBOARD
G4: Near Miss
B6: Area | C6: 46023 | D6: 46054 | E6: 46082 | F6: 46113 | G6: 46143 | H6: 46174 | I6: 46204 | J6: 46235 | K6: 46266 | L6: 46296 | M6: 46327 | N6: 46357 | O6: YTD | R6: Y2026 Rate
B7: 100 | J7: 1 | K7: 1 | O7: =SUM(C7:N7) -> 2 | Q7: OSHA Recordable Rate TRIR | X7: =Rates!O51 -> 1.3774674
B8: 200 | H8: 1 | O8: =SUM(C8:N8) -> 1 | Q8: First Aid Case Rate | X8: =Rates!O52 -> 5.5098696
B9: 300 | O9: =SUM(C9:N9) -> 0 | T9: YTD 12 MRA Rates
B10: 400 | F10: 1 | H10: 1 | O10: =SUM(C10:N10) -> 2 | Q10: OSHA Recordable Rate TRIR 12MRA | X10: =Rates!N51 -> 0.94951432 | Z10: Increase
B11: 500 | C11: 1 | O11: =SUM(C11:N11) -> 1 | Q11: First Aid Rate 12MRA | X11: =Rates!N52 -> 5.6970859 | Z11: Remain
B12: 600 | F12: 3 | G12: 1 | I12: 1 | J12: 2 | O12: =SUM(C12:N12) -> 7 | Q12: Loss Of containment Rate 12MRA | X12: =Rates!N53 -> 15.192229 | Z12: Decrease
B13: 700 | F13: 3 | J13: 2 | O13: =SUM(C13:N13) -> 5 | Q13: Property Damage Rate | X13: =Rates!N54 -> 13.293201
B14: 800 | K14: 1 | O14: =SUM(C14:N14) -> 1
B15: 900 | O15: =SUM(C15:N15) -> 0
B16: WHSE | H16: 1 | O16: =SUM(C16:N16) -> 1
B17: Maint. | O17: =SUM(C17:N17) -> 0
B18: Lab | H18: 1 | O18: =SUM(C18:N18) -> 1
B19: MUNDY | F19: 3 | G19: 1 | I19: 2 | O19: =SUM(C19:N19) -> 6
B20: Admin | F20: 1 | I20: 1 | O20: =SUM(C20:N20) -> 2
B21: 3rd Party | C21: 2 | O21: =SUM(C21:N21) -> 2
B22: TOTALS | C22: =SUM(C7:C21) -> 3 | D22: =SUM(D7:D21) -> 0 | E22: =SUM(E7:E21) -> 0 | F22: =SUM(F7:F21) -> 11 | G22: =SUM(G7:G21) -> 2 | H22: =SUM(H7:H21) -> 4 | I22: =SUM(I7:I21) -> 4 | J22: =SUM(J7:J21) -> 5 | ... N22: =SUM(N7:N21) -> 0 | O22: =SUM(C22:N22) -> 31
F23: Incidents Reported
F24: Hover Over Data Point For Details
B26: Area | C26: 46023 | D26: 46054 | E26: 46082 | F26: 46113 | G26: 46143 | H26: 46174 | I26: 46204 | J26: 46235 | K26: 46266 | L26: 46296 | M26: 46327 | N26: 46357 | O26: YTD
B27: 100 | E27: 1 | I27: 1 | O27: =SUM(C27:N27) -> 2
B28: 200 | C28: 1 | D28: 1 | H28: 1 | I28: 1 | O28: =SUM(C28:N28) -> 4
B29: 300 | C29: 1 | D29: 1 | O29: =SUM(C29:N29) -> 2
B30: 400 | C30: 1 | E30: 1 | F30: 1 | K30: 1 | O30: =SUM(C30:N30) -> 4
B31: 500 | J31: 2 | O31: =SUM(C31:N31) -> 2
B32: 600 | E32: 1 | F32: 1 | I32: 1 | O32: =SUM(C32:N32) -> 3
B33: 700 | C33: 1 | H33: 1 | O33: =SUM(C33:N33) -> 2
B34: 800 | O34: =SUM(C34:N34) -> 0
B35: 900 | O35: =SUM(C35:N35) -> 0
B36: WHSE | G36: 2 | O36: =SUM(C36:N36) -> 2
B37: Maint | O37: =SUM(C37:N37) -> 0
B38: Lab | O38: =SUM(C38:N38) -> 0
B39: Mundy | C39: 1 | D39: 2 | E39: 2 | F39: 4 | H39: 2 | I39: 1 | J39: 1 | K39: 1 | O39: =SUM(C39:N39) -> 14
B40: 3rd Party | D40: 2 | G40: 1 | I40: 1 | K40: 2 | O40: =SUM(C40:N40) -> 6
B41: TOTALS | C41: =SUM(C27:C40) -> 5 | D41: =SUM(D27:D40) -> 6 | E41: =SUM(E27:E40) -> 5 | F41: =SUM(F27:F40) -> 6 | G41: =SUM(G27:G38) -> 2 | H41: =SUM(H27:H40) -> 4 | I41: =SUM(I27:I40) -> 5 | J41: =SUM(J27:J40) -> 3 | K41: =SUM(K27:K40) -> 4 | L41: =SUM(L27:L40) -> 0 | M41: =SUM(M27:M40) -> 0 | N41: =SUM(N27:N40) -> 0 | O41: =SUM(O27:O40) -> 41

Sheet SSC-Site -21
A1: Supervisor Safety Contact | R1: PDT | S1: Number Of Trained Supervisors | V1: 20
S2: Target contact number | V2: 144 | AF2: Personal Target Per | AH2: 8 | AN2: Hand Safety Discussion | AO2: =SUM(AC2:AN2) -> 8
AN3: PPE Discrepancies Observed | AO3: =SUM(AC3:AN3) -> 0
F4: Jan | G4: Feb | H4: Mar | I4: Apr | J4: May | K4: Jun | L4: Jul | M4: Aug | N4: Sep | O4: Oct | P4: Nov | Q4: Dec | R4: Total YTD | V4: Jan | W4: Feb | X4: Mar | Y4: Apr | Z4: May | AA4: Jun | AB4: Jul | AC4: Aug | AD4: Sep | AE4: Oct | AF4: Nov | AG4: Dec | AH4: Total YTD | AN4: Housekeeping Discrepancies Corrected | AO4: =SUM(AC4:AN4) -> 0
B5: Hand Safety Discussion | R5: =SUM(F5:Q5) -> 0 | U5: Chad Kelly | V5: 4 | W5: 2 | X5: 1 | AF5: 6 | AH5: =SUM(V5:AG5) -> 13 | AN5: At Risk Behavior Observed | AO5: =SUM(AC5:AN5) -> 19
B6: Work Stoppages due to safety | F6: 3 | G6: 2 | R6: =SUM(F6:Q6) -> 5 | U6: Cory Mennor | V6: 3 | AF6: 4 | AG6: 4 | AH6: =SUM(V6:AG6) -> 11 | AN6: Safe Behavior Observed | AO6: =SUM(AC6:AN6) -> 19
B7: Work corrected after stoppages | F7: 3 | G7: 2 | R7: =SUM(F7:Q7) -> 5 | U7: Curtis Reese | AH7: =SUM(V7:AG7) -> 0 | AN7: PPE Audits performed | AO7: =SUM(AC7:AN7) -> 0
B8: Safe Behavior Observed | F8: 8 | G8: 7 | R8: =SUM(F8:Q8) -> 15 | U8: Darrel Lefear | AH8: =SUM(V8:AG8) -> 0 | AN8: Permits Issued | AO8: =SUM(AC8:AN8) -> 0
B9: At Risk Behavior Observed | F9: 7 | G9: 4 | R9: =SUM(F9:Q9) -> 11 | U9: Darrel Lefear | AH9: =SUM(V9:AG9) -> 0 | AN9: PPE Discrepancies Corrected | AO9: =SUM(AC9:AN9) -> 0
B10: JSAForms Filled Out | R10: =SUM(F10:Q10) -> 0 | U10: Dustin Traynor | V10: 2 | W10: 6 | AF10: 2 | AG10: 2 | AH10: =SUM(V10:AG10) -> 12 | AN10: Near Miss Corrected | AO10: =SUM(AC10:AN10) -> 16
B11: JSA Forms Audited | R11: =SUM(F11:Q11) -> 0 | U11: Fernando Chaves | AH11: =SUM(V11:AG11) -> 0 | AN11: Near Miss Observed | AO11: =SUM(AC11:AN11) -> 0
B12: JSA discrepancies Corrected | R12: =SUM(F12:Q12) -> 0 | U12: Jacob Sabota | AH12: =SUM(V12:AG12) -> 0 | AN12: Work Stoppages due to safety | AO12: =SUM(AC12:AN12) -> 0
B13: Permits Issued | F13: 2 | G13: 2 | R13: =SUM(F13:Q13) -> 4 | U13: James Deshotel | V13: 8 | W13: 6 | AF13: 2 | AH13: =SUM(V13:AG13) -> 16 | AN13: Work corrected after stoppages | AO13: =SUM(AC13:AN13) -> 18
B14: Permits Audited | F14: 4 | G14: 5 | R14: =SUM(F14:Q14) -> 9 | U14: Jeremay Ward | V14: 8 | W14: 7 | AF14: 2 | AG14: 2 | AH14: =SUM(V14:AG14) -> 19 | AN14: JSAForms Filled Out | AO14: =SUM(AC14:AN14) -> 23
B15: Permit discrepancies corrected | F15: 1 | G15: 3 | R15: =SUM(F15:Q15) -> 4 | U15: Jeremy Metz | V15: 1 | W15: 2 | AF15: 4 | AG15: 2 | AH15: =SUM(V15:AG15) -> 9 | AN15: JSA Forms Audited | AO15: =SUM(AC15:AN15) -> 15
B16: PPE Audits performed | F16: 5 | G16: 3 | R16: =SUM(F16:Q16) -> 8 | U16: Jessica Kafka | AH16: =SUM(V16:AG16) -> 0 | AN16: JSA discrepancies Corrected | AO16: =SUM(AC16:AN16) -> 0
B17: PPE Discrepancies Observed | F17: 6 | G17: 4 | R17: =SUM(F17:Q17) -> 10 | U17: Micha Barnes | AH17: =SUM(V17:AG17) -> 0 | AN17: Permits Audited | AO17: =SUM(AC17:AN17) -> 0
B18: PPE Discrepancies Corrected | F18: 4 | G18: 2 | R18: =SUM(F18:Q18) -> 6 | U18: Mike Casto | V18: 5 | W18: 5 | AF18: 2 | AG18: 4 | AH18: =SUM(V18:AG18) -> 16 | AN18: Permit discrepancies corrected | AO18: =SUM(AC18:AN18) -> 22
B19: Housekeeping inspections performed | F19: 9 | G19: 3 | R19: =SUM(F19:Q19) -> 12 | U19: Mike Lynn | AH19: =SUM(V19:AG19) -> 0 | AN19: Housekeeping inspections performed | AO19: =SUM(AC19:AN19) -> 0
B20: Housekeeping Discrepancies Observed | F20: 9 | G20: 2 | R20: =SUM(F20:Q20) -> 11 | U20: Richie Watson | AH20: =SUM(V20:AG20) -> 0 | AN20: Housekeeping Discrepancies Observed | AO20: =SUM(AC20:AN20) -> 0
B21: Housekeeping Discrepancies Corrected | F21: 8 | G21: 3 | R21: =SUM(F21:Q21) -> 11 | U21: Robert Cooper | AH21: =SUM(V21:AG21) -> 0 | AN21: LO/TO Reviewed | AO21: =SUM(AC21:AN21) -> 0
B22: LO/TO Reviewed | F22: 5 | R22: =SUM(F22:Q22) -> 5 | U22: Rodney Gaspard | AF22: 4 | AH22: =SUM(V22:AG22) -> 4 | AN22: LO/TO Discrepancies observed | AO22: =SUM(AC22:AN22) -> 8
B23: LO/TO Discrepancies observed | F23: 7 | G23: 1 | R23: =SUM(F23:Q23) -> 8 | U23: Ken Brandon | AH23: =SUM(V23:AG23) -> 0 | AN23: LO/TO Discrepancies corrected | AO23: =SUM(AC23:AN23) -> 0
B24: LO/TO Discrepancies corrected | F24: 5 | R24: =SUM(F24:Q24) -> 5 | U24: John Boyd | V24: 4 | W24: 3 | AF24: 2 | AH24: =SUM(V24:AG24) -> 9 | AN24: Near Miss Reported | AO24: =SUM(AC24:AN24) -> 11
B25: Near Miss Observed | F25: 1 | G25: 2 | R25: =SUM(F25:Q25) -> 3 | AH25: =SUM(V25:AG25) -> 0 | AN25: Working Interface Observations | AO25: =SUM(AC25:AN25) -> 0
B26: Near Miss Reported | R26: =SUM(F26:Q26) -> 0 | AH26: =SUM(V26:AG26) -> 0 | AN26: Incidents reported by team | AO26: =SUM(AC26:AN26) -> 0
B27: Near Miss Corrected | F27: 1 | G27: 2 | R27: =SUM(F27:Q27) -> 3 | AH27: =SUM(V27:AG27) -> 0 | AN27: Incidents reports entered into tracking | AO27: =SUM(AC27:AN27) -> 0
B28: Working Interface Observations | G28: 1 | R28: =SUM(F28:Q28) -> 1 | AH28: =SUM(V28:AG28) -> 0 | AN28: Safety Interaction with Team Member | AO28: =SUM(AC28:AN28) -> 0
B29: Incidents reported by team | F29: 1 | G29: 5 | R29: =SUM(F29:Q29) -> 6 | AH29: =SUM(V29:AG29) -> 0 | AN29: Positive safe feedback given | AO29: =SUM(AC29:AN29) -> 0
B30: Incidents reports entered into tracking | F30: 2 | G30: 6 | R30: =SUM(F30:Q30) -> 8 | AH30: =SUM(V30:AG30) -> 0 | AN30: At-Risk guidance feedback Provided | AO30: =SUM(AC30:AN30) -> 0
B31: Safety Interaction with Team Member | F31: 8 | G31: 4 | R31: =SUM(F31:Q31) -> 12 | AH31: =SUM(V31:AG31) -> 0
B32: Positive safe feedback given | F32: 14 | G32: 11 | R32: =SUM(F32:Q32) -> 25 | AH32: =SUM(V32:AG32) -> 0
B33: At-Risk guidance feedback Provided | F33: 2 | G33: 1 | R33: =SUM(F33:Q33) -> 3 | AH33: =SUM(V33:AG33) -> 0
V35: =COUNTA(V5:V33) -> 8 | W35: =COUNTA(W5:W33) -> 7 | X35: =COUNTA(X5:X33) -> 1 | Y35: =COUNTA(Y5:Y33) -> 0 | Z35: =COUNTA(Z5:Z33) -> 0 | AA35: =COUNTA(AA5:AA33) -> 0 | AB35: =COUNTA(AB5:AB33) -> 0 | AC35: =COUNTA(AC5:AC33) -> 0 | ... AG35: =COUNTA(AG5:AG33) -> 5
R36: TOTOYTD | V36: 144 | W36: 144 | X36: 144 | Y36: 144 | Z36: 144 | AA36: 144 | AB36: 144 | AC36: 144 | AD36: 144 | AE36: 144 | AF36: 144 | AG36: 144 | AH36: TOTOYTD
E37: Total MTD | F37: =SUM(F5:F33) -> 115 | G37: =SUM(G5:G33) -> 75 | H37: =SUM(H5:H33) -> 0 | I37: =SUM(I5:I33) -> 0 | J37: =SUM(J5:J33) -> 0 | K37: =SUM(K5:K33) -> 0 | L37: =SUM(L5:L33) -> 0 | M37: =SUM(M5:M33) -> 0 | ... R37: =SUM(R5:R33) -> 190 | U37: MTD Total | V37: =SUM(V5:V33) -> 35 | W37: =SUM(W5:W33) -> 31 | X37: =SUM(X5:X33) -> 1 | Y37: =SUM(Y5:Y33) -> 0 | Z37: =SUM(Z5:Z33) -> 0 | AA37: =SUM(AA5:AA33) -> 0 | AB37: =SUM(AB5:AB33) -> 0 | AC37: =SUM(AC5:AC33) -> 0 | ... AG37: =SUM(AG5:AG33) -> 14 | AH37: =SUM(AH5:AH34) -> 109
V38: =V37/$V36 -> 0.24305556 | W38: =W37/$V36 -> 0.21527778 | X38: =X37/$V36 -> 0.0069444444 | Y38: =Y37/$V36 -> 0 | Z38: =Z37/$V36 -> 0 | AA38: =AA37/$V36 -> 0 | AB38: =AB37/$V36 -> 0 | AC38: =AC37/$V36 -> 0 | ... AE38: =AE37/$V36 -> 0 | AF38: =AF35/$V1 -> 0.45 | AG38: =AG37/$V36 -> 0.097222222 | AI38: =AVERAGE(V38:Y38) -> 0.11631944 | AJ38: Avg Participation
V39: 1 | W39: 1 | X39: 1 | Y39: 1 | Z39: 1 | AA39: 1 | AB39: 1 | AC39: 1 | AD39: 1 | AE39: 1 | AF39: 1 | AG39: 1

Sheet Area Data
B7: AREA | C7: First Aid | D7: Recordable Injury | E7: Lost time injury | F7: Restricted | G7: Occupational Ilness | H7: Hazardous Condition | I7: Spill/ Release Release | J7: Fire | K7: Powered Industrial Vehicle Accident | L7: Property/ Equipment Damage | M7: Equipment Failure | N7: Non-Work Related | O7: Regulatory | P7: PSIF
B9: 100 | I9: 2 | Q9: =SUM(C9:P9) -> 2
B10: 200 | C10: 1 | I10: 3 | Q10: =SUM(C10:P10) -> 4
B11: 300 | I11: 2 | Q11: =SUM(C11:P11) -> 2
B12: 400 | I12: 3 | L12: 1 | Q12: =SUM(C12:P12) -> 4
B13: 500 | I13: 2 | Q13: =SUM(C13:P13) -> 2
B14: 600 | C14: 1 | I14: 1 | L14: 1 | Q14: =SUM(C14:P14) -> 3
B15: 700 | H15: 1 | I15: 1 | P15: 1 | Q15: =SUM(C15:P15) -> 3
B16: 800 | Q16: =SUM(C16:P16) -> 0
B17: 900 | Q17: =SUM(C17:P17) -> 0
B18: WHSE | H18: 1 | K18: 1 | L18: 1 | Q18: =SUM(C18:P18) -> 3
B19: Maint | Q19: =SUM(C19:P19) -> 0
B20: Lab | Q20: =SUM(C20:P20) -> 0
B21: Mundy | C21: 2 | D21: 1 | J21: 1 | K21: 8 | L21: 7 | N21: 2 | P21: 4 | Q21: =SUM(C21:P21) -> 25
B22: 3rd Patry | C22: 1 | H22: 2 | L22: 2 | N22: 3 | Q22: =SUM(C22:P22) -> 8
C23: =SUM(C9:C22) -> 5 | D23: =SUM(D9:D22) -> 1 | E23: =SUM(E9:E22) -> 0 | F23: =SUM(F9:F22) -> 0 | G23: =SUM(G9:G22) -> 0 | H23: =SUM(H9:H22) -> 4 | I23: =SUM(I9:I22) -> 14 | J23: =SUM(J9:J22) -> 1 | ... M23: =SUM(M9:M22) -> 0 | O23: =SUM(O9:O22) -> 0 | P23: =SUM(P9:P22) -> 5
A29: Incidents | B29: Area | C29: YTD
B30: 100 | C30: =Dash!O27 -> 2
B31: 200 | C31: =Dash!O28 -> 4
B32: 300 | C32: =Dash!O29 -> 2
B33: 400 | C33: =Dash!O30 -> 4
B34: 500 | C34: =Dash!O31 -> 2
B35: 600 | C35: =Dash!O32 -> 3
B36: 700 | C36: =Dash!O33 -> 2
B37: 800 | C37: =Dash!O34 -> 0
B38: 900 | C38: =Dash!O35 -> 0
B39: WHSE | C39: =Dash!O36 -> 2
B40: Maint | C40: =Dash!O37 -> 0
B41: Lab | C41: =Dash!O38 -> 0
B42: Mundy | C42: =Dash!O39 -> 14
B43: 3rd Party | C43: =Dash!O40 -> 6
C44: =Dash!O41 -> 41
A47: Human Error | B47: Area | C47: YTD | E47: Mundy | F47: 13
B48: 100 | E48: 200 | F48: 4
B49: 200 | C49: 2 | E49: 3rd Party | F49: 4
B50: 300 | E50: 400 | F50: 3
B51: 400 | C51: 1 | E51: 600 | F51: 3
B52: 500 | E52: 100 | F52: 2
B53: 600 | C53: 2 | E53: 300 | F53: 2
B54: 700 | C54: 1 | E54: 500 | F54: 2
...

Sheet Incident Data
P2: HSE Incidents | BG2: Target | BH2: 60 | BI2: 60 | BJ2: 60 | BK2: 60 | BL2: 60 | BM2: 60 | BN2: 60 | BO2: 60 | BP2: 60 | BQ2: 60 | BR2: 60 | BS2: 60 | BT2: 60
A3: NEAR MISS/ INCIDENT TOTAL YTD | P3: 2025 | Q3: 41 | BG3: Actual
P4: 2026 | Q4: =N7 -> 41
B5: Jan | C5: Feb | D5: Mar | E5: Apr | F5: May | G5: Jun | H5: Jul | I5: Aug | J5: Sep | K5: Oct | L5: Nov | M5: Dec | N5: Total
A6: Near Miss | B6: {=Dash!C22:N22} -> 3 | C6: 0 | D6: 0 | E6: 11 | F6: 2 | G6: 4 | H6: 4 | I6: 5 | J6: 2 | K6: 0 | L6: 0 | M6: 0 | N6: =SUM(B6:M6) -> 31 | AH6: Injury Cause | BA6: Contact By | BG6: Environmental Excursions | BH6: JAN | BI6: FEB | BJ6: MAR | BK6: APR | BL6: MAY | BM6: JUN | BN6: JUL | BO6: AUG | BP6: SEP | BQ6: OCT | BR6: NOV | BS6: DEC | BT6: Total
A7: Incident | B7: =Dash!$C$41 -> 5 | C7: =Dash!D41 -> 6 | D7: =Dash!E41 -> 5 | E7: =Dash!F41 -> 6 | F7: =Dash!G41 -> 2 | G7: =Dash!H41 -> 4 | H7: =Dash!I41 -> 5 | I7: =Dash!J41 -> 3 | J7: =Dash!K41 -> 4 | ... M7: =Dash!N41 -> 0 | N7: =Dash!$O$41 -> 41 | P7: Near-Miss | BA7: Contact With | BB7: 1 | BG7: 2024 | BT7: =SUM(BH7:BS7) -> 0
P8: 2025 | Q8: 38 | AJ8: Jan | AK8: Feb | AL8: Mar | AM8: Apr | AN8: May | AO8: Jun | AP8: Jul | AQ8: Aug | AR8: Sep | AS8: Oct | AT8: Nov | AU8: Dec | AV8: YTD | BA8: Caught In | BB8: 1 | BG8: 2025 | BT8: =SUM(BH8:BS8) -> 0 | BU8: =(BT8-BT7)/BT7 -> #DIV/0!
A9: Incident type | B9: Jan | C9: Feb | D9: Mar | E9: Apr | F9: May | G9: Jun | H9: Jul | I9: Aug | J9: Sep | K9: Oct | L9: Nov | M9: Dec | N9: Total | P9: 2026 | Q9: =N6 -> 31 | AH9: Caught Between | AJ9: 1 | AV9: =SUM(AJ9:AU9) -> 1 | BA9: Slip/Trip (No Fall)
AH10: Caught In | AQ10: 1 | AV10: =SUM(AJ10:AU10) -> 1 | BA10: Sprain
A11: First Aid | B11: 1 | D11: 1 | E11: 2 | J11: 1 | N11: =SUM(B11:M11) -> 5 | P11: Near Miss Potential | Q11: Jan | R11: Feb | S11: Mar | T11: Apr | U11: May | V11: Jun | W11: Jul | X11: Aug | Y11: Sep | Z11: Oct | AA11: Nov | AB11: Dec | AC11: Total | AH11: Caught On | AV11: =SUM(AJ11:AU11) -> 0 | BA11: Caught Between | BB11: 1
A12: Recordable Injury | I12: 1 | N12: =SUM(B12:M12) -> 1 | P12: SIF | Q12: 2 | T12: 2 | V12: 1 | W12: 1 | AC12: =SUM(Q12:AB12) -> 6 | AH12: Contact By | AM12: 1 | AV12: =SUM(AJ12:AU12) -> 1 | BA12: Caught On | BB12: 0
A13: Lost time injury | N13: =SUM(B13:M13) -> 0 | P13: Lost Time Injury | T13: 5 | V13: 1 | W13: 2 | AC13: =SUM(Q13:AB13) -> 8 | AH13: Contact With | AM13: 1 | AV13: =SUM(AJ13:AU13) -> 1 | BA13: Exposure | BB13: 1
A14: Recordable | N14: =SUM(B14:M14) -> 0 | P14: Exposure | Q14: 1 | T14: 1 | U14: 1 | X14: 3 | AC14: =SUM(Q14:AB14) -> 6 | AH14: Exposure | AL14: 1 | AV14: =SUM(AJ14:AU14) -> 1 | BA14: Fall Below | BB14: 0
A15: Restricted | N15: =SUM(B15:M15) -> 0 | P15: Fire | T15: 1 | U15: 1 | V15: 2 | X15: 2 | AC15: =SUM(Q15:AB15) -> 6 | AH15: Fall Below | AV15: =SUM(AJ15:AU15) -> 0 | BA15: Fall Same Level | BB15: 0
A16: Occupational Ilness | N16: =SUM(B16:M16) -> 0 | P16: Property Damage | Q16: 1 | T16: 1 | V16: 2 | AC16: =SUM(Q16:AB16) -> 4 | AH16: Fall Same Level | AV16: =SUM(AJ16:AU16) -> 0 | BA16: Foreign Body | BB16: 0
A17: Spill/ Release | B17: 1 | C17: 2 | D17: 2 | E17: 1 | G17: 2 | H17: 3 | I17: 2 | J17: 1 | N17: =SUM(B17:M17) -> 14 | P17: Environmental Release | T17: 1 | X17: 3 | Y17: 1 | AC17: =SUM(Q17:AB17) -> 5 | AH17: Foreign Body | AV17: =SUM(AJ17:AU17) -> 0 | BA17: Strain (Overexertion) | BB17: 0
A18: Fire | D18: 1 | N18: =SUM(B18:M18) -> 1 | P18: Buisness Interuption | Q18: 1 | V18: 2 | AC18: =SUM(Q18:AB18) -> 3 | AH18: Slip/Trip (No Fall) | AV18: =SUM(AJ18:AU18) -> 0 | BA18: Struck Against | BB18: 0
A19: Hazardous Condition | B19: 1 | C19: 2 | F19: 1 | N19: =SUM(B19:M19) -> 4
A20: Powered Industrial Vehicle Accident | C20: 1 | E20: 3 | F20: 1 | G20: 2 | H20: 1 | J20: 1 | N20: =SUM(B20:M20) -> 9 | AH20: Sprain | AV20: =SUM(AJ20:AU20) -> 0 | BA20: Struck By | BB20: 1
A21: Property Damage | B21: 1 | C21: 1 | F21: 2 | H21: 2 | N21: =SUM(B21:M21) -> 6 | P21: Near Miss Potential | Q21: Total | AH21: Strain (Overexertion) | AV21: =SUM(AJ21:AU21) -> 0 | BF21: =SUM(N11:N20) -> 34
A22: Equipment Damage | B22: 0 | D22: 1 | E22: 4 | G22: 2 | J22: 1 | N22: =SUM(B22:M22) -> 8 | P22: Lost Time Injury | Q22: 8 | AH22: Struck Against | AV22: =SUM(AJ22:AU22) -> 0
A23: Non-Work-Related | B23: 1 | C23: 1 | F23: 1 | J23: 1 | N23: =SUM(B23:M23) -> 4 | P23: SIF | Q23: 6
A24: Regulatory | N24: =SUM(B24:M24) -> 0 | P24: Exposure | Q24: 6 | AH24: Struck By | AR24: 1 | AV24: =SUM(AJ24:AU24) -> 1
A25: PSIF | B25: 2 | E25: 2 | I25: 1 | N25: =SUM(B25:M25) -> 5 | P25: Fire | Q25: 6 | AH25: Monthly Totals By Cause | AJ25: =SUM(AJ9:AJ24) -> 1
P26: Property Damage | Q26: 4 | AW26: =SUM(AV9:AV24) -> 6
B27: =SUM(B22,B21) -> 1 | C27: =SUM(C22,C21) -> 1 | D27: =SUM(D22,D21) -> 1 | E27: =SUM(E22,E21) -> 4 | F27: =SUM(F22,F21) -> 2 | I27: =SUM(I22,I21) -> 0 | J27: =SUM(J22,J21) -> 1 | K27: =SUM(K22,K21) -> 0 | L27: =SUM(L22,L21) -> 0 | M27: =SUM(M22,M21) -> 0 | P27: Environmental Release | Q27: 4
A28: LOC CONTRIBUTING FACTORS | P28: Buisness Interuption | Q28: 3 | BF28: =BW8131 -> 0
B30: Jan | C30: Feb | D30: Mar | E30: Apr | F30: May | G30: Jun | H30: Jul | I30: Aug | J30: Sep | K30: Oct | L30: Nov | M30: Dec | N30: Total
A31: Mechanical Integrity | B31: 1 | C31: 1 | D31: 2 | G31: 2 | H31: 2 | I31: 1
A32: Human Error | C32: 1 | E32: 1 | H32: 1 | I32: 1
A33: Other | J33: 1
B34: JAN | C34: FEB | D34: MAR | E34: APR | F34: MAY | G34: JUN | H34: JUL | I34: AUG | J34: SEP | K34: OCT | L34: NOV | M34: DEC
A35: Accum. Mechanical Integrity | B35: =B31 -> 1 | C35: =SUM(B35,C31) -> 2 | D35: =SUM(C35,D31) -> 4 | E35: =SUM(D35,E31) -> 4 | H35: =SUM(G35,H31) -> 2 | J35: =SUM(I35,J31) -> 0 | AH35: Body Part Involved
A36: Accumulating Human Error | B36: =B32 -> 0 | C36: =SUM(B36,C32) -> 1 | D36: =SUM(C36,D32) -> 1 | E36: =SUM(D36,E32) -> 2 | AJ36: Jan | AK36: Feb | AL36: Mar | AM36: Apr | AN36: May | AO36: Jun | AP36: Jul | AQ36: Aug | AR36: Sep | AS36: Oct | AT36: Nov | AU36: Dec | AV36: YTD Body Part | AX36: Eye | AY36: 1
AH37: Abdomen | AV37: =SUM(AJ37:AU37) -> 0 | AX37: Knee
P38: Near Miss Cause | Q38: Jan | R38: Feb | S38: Mar | T38: Apr | U38: May | V38: Jun | W38: Jul | X38: Aug | Y38: Sep | Z38: Oct | AA38: Nov | AB38: Dec | AC38: Total | AH38: Ankle | AV38: =SUM(AJ38:AU38) -> 0 | AX38: Feet
P39: Human Performance | Q39: 2 | T39: 6 | V39: 2 | W39: 3 | AC39: =SUM(Q39:AB39) -> 13 | AH39: Arm | AV39: =SUM(AJ39:AU39) -> 0 | AX39: Fingers | AY39: 4
P40: Communication | V40: 1 | AC40: =SUM(Q40:AB40) -> 1 | AH40: Back | AV40: =SUM(AJ40:AU40) -> 0 | AX40: Hand
P41: Training / Competency | V41: 2 | AC41: =SUM(Q41:AB41) -> 2 | AH41: Body General | AV41: =SUM(AJ41:AU41) -> 0 | AX41: Abdomen | AY41: 0
P42: Procedures | V42: 1 | AC42: =SUM(Q42:AB42) -> 1 | AH42: Buttocks | AV42: =SUM(AJ42:AU42) -> 0 | AX42: Ankle | AY42: 0
...

Sheet Behavior
A1: PARETO Of Behaviors Involved in Accidents
B2: Behavior Extracted | C2: BEHAVIORS
B3: Number of Behaviors | C3: Percent of Accident
A4: Pre & Post Job Inspection | B4: 9 | C4: =B4/B$30 -> 0.2195122
A5: Communications Of Hazards | B5: 4 | C5: =B5/B$30 -> 0.097560976
A6: Eyes On Path | B6: 12 | C6: =B6/B$30 -> 0.29268293
A7: Knowledge of Task | B7: 4 | C7: =B7/B$30 -> 0.097560976
A8: Line Of Fire | B8: 2 | C8: =B8/B$30 -> 0.048780488
A9: Pinch Points | B9: 3 | C9: =B9/B$30 -> 0.073170732
A10: Energy Isolation | B10: 4 | C10: =B10/B$30 -> 0.097560976
A11: Get Assistance | B11: 3 | C11: =B11/B$30 -> 0.073170732
A12: Housekeeping | C12: =B12/B$30 -> 0
A13: Walking & Working Surfaces | C13: =B13/B$30 -> 0
A14: PPE Eye | B14: 1 | C14: =B14/B$30 -> 0.024390244
A15: PPE Hands | B15: 2 | C15: =B15/B$30 -> 0.048780488
A16: Eyes On Task | C16: =B16/B$30 -> 0
A17: Hot work | C17: =B17/B$30 -> 0
A18: Tool Equipment Selection | C18: =B18/B$30 -> 0
A19: Ascending / Descending | C19: =B19/B$30 -> 0
A20: PPE Respiritory | C20: =B20/B$30 -> 0
A21: Tool Use | C21: =B21/B$30 -> 0
A22: Lifting & Lowering | C22: =B22/B$30 -> 0
A23: Twisting | C23: =B23/B$30 -> 0
A24: Pushing & Pulling | C24: =B24/B$30 -> 0
A25: PPE Body | C25: =B25/B$30 -> 0
A26: Temp Extreme | C26: =B26/B$30 -> 0
A27: Confined Space | C27: =B27/B$30 -> 0
A29: Total Number of Behaviors | B29: =SUM(B4:B28) -> 44 | C29: =B29/B$30 -> 1.0731707
A30: Total Number of Incident Reports 2025 | B30: =Dash!O41 -> 41
A31: Average Behaviors Per Incident Report | B31: =B29/B30 -> 1.0731707

Sheet Rolling
B1: Month | D1: Manhours Manhours | E1: Contractor Manhours | F1: Combined Contractor & | G1: Fatalities | H1: Lost Time | I1: LWD/# of days away | J1: LTI Global | K1: LTI | L1: Restricted | M1: Restricted Rate | N1: Restricted # of days | O1: LTI/LWCR (Employee) | P1: Recordables | Q1: (RIR)Recordable Rate | S1: Fatalities | T1: Contractor Lost time | U1: Contractor LWD/# of days away | V1: Global LTI (Contractor) | W1: Contractor Restricted | X1: Contractor Restricted # of days | Y1: Global LTI/LWCR (Contractor) | Z1: Contractor Recordables | AA1: (RIR)Recordable Rate Contractor | AB1: LTI (Employee + Contractor) | AC1: LTI + RWC (Employee + Contractor) | AD1: Employee / Contractor Recordables
A2: 2021 | B2: Jan | F2: =D2+E2 -> 0
A3: 2021 | B3: Feb | F3: =D3+E3 -> 0
A4: 2021 | B4: Mar | F4: =D4+E4 -> 0 | J4: =H4*1000000/D4 -> #DIV/0! | K4: =H4*200000/D4 -> #DIV/0! | M4: =SUM(L4)*200000/D4 -> #DIV/0! | O4: =H4+L4*1000000/D4 -> #DIV/0! | Q4: =SUM(G4,H4,L4,P4)*200000/D4 -> #DIV/0! | V4: =SUM(T4)*1000000/E5 -> #DIV/0! | W4: 1 | Y4: =SUM(T4,W4)*1000000/E4 -> #DIV/0! | Z4: 1 | AA4: =Z4*1000000/E4 -> #DIV/0! | AB4: =SUM(H4,T4)*1000000/F4 -> #DIV/0! | AC4: =SUM(H4,L4,T4,W4)*1000000/F4 -> #DIV/0! | AD4: =SUM(P4,Z4) -> 1
A5: 2021 | B5: Apr | F5: =D5+E5 -> 0 | J5: =H5*1000000/D5 -> #DIV/0! | K5: =H5*200000/D5 -> #DIV/0! | M5: =SUM(L5)*200000/D5 -> #DIV/0! | O5: =H5+L5*1000000/D5 -> #DIV/0! | Q5: =SUM(G5,H5,L5,P5)*200000/D5 -> #DIV/0! | V5: =SUM(T5)*1000000/E6 -> #DIV/0! | Y5: =SUM(T5,W5)*1000000/E5 -> #DIV/0! | AA5: =Z5*1000000/E5 -> #DIV/0! | AB5: =SUM(H5,T5)*1000000/F5 -> #DIV/0! | AC5: =SUM(H5,L5,T5,W5)*1000000/F5 -> #DIV/0! | AD5: =SUM(P5,Z5) -> 0
A6: 2021 | B6: May | F6: =D6+E6 -> 0 | J6: =H6*1000000/D6 -> #DIV/0! | K6: =H6*200000/D6 -> #DIV/0! | M6: =SUM(L6)*200000/D6 -> #DIV/0! | O6: =H6+L6*1000000/D6 -> #DIV/0! | P6: 1 | Q6: =SUM(G6,H6,L6,P6)*200000/D6 -> #DIV/0! | V6: =SUM(T6)*1000000/E7 -> #DIV/0! | X6: 9 | Y6: =SUM(T6,W6)*1000000/E6 -> #DIV/0! | AA6: =Z6*1000000/E6 -> #DIV/0! | AB6: =SUM(H6,T6)*1000000/F6 -> #DIV/0! | AC6: =SUM(H6,L6,T6,W6)*1000000/F6 -> #DIV/0! | AD6: =SUM(P6,Z6) -> 1
A7: 2021 | B7: Jun | F7: =D7+E7 -> 0 | J7: =H7*1000000/D7 -> #DIV/0! | K7: =H7*200000/D7 -> #DIV/0! | M7: =SUM(L7)*200000/D7 -> #DIV/0! | O7: =H7+L7*1000000/D7 -> #DIV/0! | P7: 1 | Q7: =SUM(G7,H7,L7,P7)*200000/D7 -> #DIV/0! | V7: =SUM(T7)*1000000/E8 -> #DIV/0! | Y7: =SUM(T7,W7)*1000000/E7 -> #DIV/0! | AA7: =Z7*1000000/E7 -> #DIV/0! | AB7: =SUM(H7,T7)*1000000/F7 -> #DIV/0! | AC7: =SUM(H7,L7,T7,W7)*1000000/F7 -> #DIV/0! | AD7: =SUM(P7,Z7) -> 1
A8: 2021 | B8: Jul | F8: =D8+E8 -> 0 | J8: =H8*1000000/D8 -> #DIV/0! | K8: =H8*200000/D8 -> #DIV/0! | L8: 1 | M8: =SUM(L8)*200000/D8 -> #DIV/0! | N8: 6 | O8: =H8+L8*1000000/D8 -> #DIV/0! | Q8: =SUM(G8,H8,L8,P8)*200000/D8 -> #DIV/0! | V8: =SUM(T8)*1000000/E9 -> #DIV/0! | W8: 2 | X8: 27 | Y8: =SUM(T8,W8)*1000000/E8 -> #DIV/0! | Z8: 2 | AA8: =Z8*1000000/E8 -> #DIV/0! | AB8: =SUM(H8,T8)*1000000/F8 -> #DIV/0! | AC8: =SUM(H8,L8,T8,W8)*1000000/F8 -> #DIV/0! | AD8: =SUM(P8,Z8) -> 2
A9: 2021 | B9: Aug | F9: =D9+E9 -> 0 | J9: =H9*1000000/D9 -> #DIV/0! | K9: =H9*200000/D9 -> #DIV/0! | L9: 1 | M9: =SUM(L9)*200000/D9 -> #DIV/0! | N9: 6 | O9: =H9+L9*1000000/D9 -> #DIV/0! | P9: 2 | Q9: =SUM(G9,H9,L9,P9)*200000/D9 -> #DIV/0! | T9: 1 | U9: 13 | V9: =SUM(T9)*1000000/E10 -> #DIV/0! | X9: 31 | Y9: =SUM(T9,W9)*1000000/E9 -> #DIV/0! | Z9: 1 | AA9: =Z9*1000000/E9 -> #DIV/0! | AB9: =SUM(H9,T9)*1000000/F9 -> #DIV/0! | AC9: =SUM(H9,L9,T9,W9)*1000000/F9 -> #DIV/0! | AD9: =SUM(P9,Z9) -> 3
A10: 2021 | B10: Sep | F10: =D10+E10 -> 0 | J10: =H10*1000000/D10 -> #DIV/0! | K10: =H10*200000/D10 -> #DIV/0! | M10: =SUM(L10)*200000/D10 -> #DIV/0! | N10: 2 | O10: =H10+L10*1000000/D10 -> #DIV/0! | P10: 1 | Q10: =SUM(G10,H10,L10,P10)*200000/D10 -> #DIV/0! | V10: =SUM(T10)*1000000/E11 -> #DIV/0! | W10: 1 | X10: 31 | Y10: =SUM(T10,W10)*1000000/E10 -> #DIV/0! | AA10: =Z10*1000000/E10 -> #DIV/0! | AB10: =SUM(H10,T10)*1000000/F10 -> #DIV/0! | AC10: =SUM(H10,L10,T10,W10)*1000000/F10 -> #DIV/0! | AD10: =SUM(P10,Z10) -> 1
A11: 2021 | B11: Oct | F11: =D11+E11 -> 0 | J11: =H11*1000000/D11 -> #DIV/0! | K11: =H11*200000/D11 -> #DIV/0! | M11: =SUM(L11)*200000/D11 -> #DIV/0! | N11: 2 | O11: =H11+L11*1000000/D11 -> #DIV/0! | P11: 1 | Q11: =SUM(G11,H11,L11,P11)*200000/D11 -> #DIV/0! | T11: 1 | U11: 24 | V11: =SUM(T11)*1000000/E12 -> #DIV/0! | W11: 1 | X11: 18 | Y11: =SUM(T11,W11)*1000000/E11 -> #DIV/0! | Z11: 2 | AA11: =Z11*1000000/E11 -> #DIV/0! | AB11: =SUM(H11,T11)*1000000/F11 -> #DIV/0! | AC11: =SUM(H11,L11,T11,W11)*1000000/F11 -> #DIV/0! | AD11: =SUM(P11,Z11) -> 3
A12: 2021 | B12: Nov | F12: =D12+E12 -> 0 | H12: 1 | I12: 5 | J12: =H12*1000000/D12 -> #DIV/0! | K12: =H12*200000/D12 -> #DIV/0! | M12: =SUM(L12)*200000/D12 -> #DIV/0! | N12: 2 | O12: =SUM(H12,L12)*1000000/D12 -> #DIV/0! | Q12: =SUM(G12,H12,L12,P12)*200000/D12 -> #DIV/0! | U12: 30 | V12: =SUM(T12)*1000000/E13 -> #DIV/0! | W12: 1 | X12: 58 | Y12: =SUM(T12,W12)*1000000/E12 -> #DIV/0! | AA12: =Z12*1000000/E12 -> #DIV/0! | AB12: =SUM(H12,T12)*1000000/F12 -> #DIV/0! | AC12: =SUM(H12,L12,T12,W12)*1000000/F12 -> #DIV/0! | AD12: =SUM(P12,Z12) -> 0
A13: 2021 | B13: Dec | F13: =D13+E13 -> 0 | H13: 1 | I13: 43 | J13: =H13*1000000/D13 -> #DIV/0! | K13: =H13*200000/D13 -> #DIV/0! | M13: =SUM(L13)*200000/D13 -> #DIV/0! | O13: =SUM(H13,L13)*1000000/D13 -> #DIV/0! | P13: 1 | Q13: =SUM(G13,H13,L13,P13)*200000/D13 -> #DIV/0! | U13: 31 | V13: =SUM(T13)*1000000/E13 -> #DIV/0! | X13: 23 | Y13: =SUM(T13,W13)*1000000/E13 -> #DIV/0! | AA13: =Z13*1000000/E13 -> #DIV/0! | AB13: =SUM(H13,T13)*1000000/F13 -> #DIV/0! | AC13: =SUM(H13,L13,T13,W13)*1000000/F13 -> #DIV/0! | AD13: =SUM(P13,Z13) -> 1
A14: 2022 | B14: Jan | F14: =D14+E14 -> 0 | J14: =H14*1000000/D14 -> #DIV/0! | K14: =H14*200000/D14 -> #DIV/0! | M14: =SUM(L14)*200000/D14 -> #DIV/0! | O14: =SUM(H14,L14)*1000000/D14 -> #DIV/0! | Q14: =SUM(G14,H14,L14,P14)*200000/D14 -> #DIV/0! | V14: =SUM(T14)*1000000/E15 -> #DIV/0! | Y14: =SUM(T14,W14)*1000000/E14 -> #DIV/0! | AA14: =Z14*1000000/E14 -> #DIV/0! | AB14: =SUM(H14,T14)*1000000/F14 -> #DIV/0! | AC14: =SUM(H14,L14,T14,W14)*1000000/F14 -> #DIV/0! | AD14: =SUM(P14,Z14) -> 0
A15: 2022 | B15: Feb | F15: =D15+E15 -> 0 | J15: =H15*1000000/D15 -> #DIV/0! | K15: =H15*200000/D15 -> #DIV/0! | M15: =SUM(L15)*200000/D15 -> #DIV/0! | O15: =SUM(H15,L15)*1000000/D15 -> #DIV/0! | Q15: =SUM(G15,H15,L15,P15)*200000/D15 -> #DIV/0! | V15: =SUM(T15)*1000000/E16 -> #DIV/0! | Y15: =SUM(T15,W15)*1000000/E15 -> #DIV/0! | AA15: =Z15*1000000/E15 -> #DIV/0! | AB15: =SUM(H15,T15)*1000000/F15 -> #DIV/0! | AC15: =SUM(H15,L15,T15,W15)*1000000/F15 -> #DIV/0! | AD15: =SUM(P15,Z15) -> 0
A16: 2022 | B16: Mar | F16: =D16+E16 -> 0 | J16: =H16*1000000/D16 -> #DIV/0! | K16: =H16*200000/D16 -> #DIV/0! | M16: =SUM(L16)*200000/D16 -> #DIV/0! | O16: =SUM(H16,L16)*1000000/D16 -> #DIV/0! | Q16: =SUM(G16,H16,L16,P16)*200000/D16 -> #DIV/0! | V16: =SUM(T16)*1000000/E17 -> #DIV/0! | Y16: =SUM(T16,W16)*1000000/E16 -> #DIV/0! | AA16: =Z16*1000000/E16 -> #DIV/0! | AB16: =SUM(H16,T16)*1000000/F16 -> #DIV/0! | AC16: =SUM(H16,L16,T16,W16)*1000000/F16 -> #DIV/0! | AD16: =SUM(P16,Z16) -> 0
A17: 2022 | B17: Apr | F17: =D17+E17 -> 0 | J17: =H17*1000000/D17 -> #DIV/0! | K17: =H17*200000/D17 -> #DIV/0! | M17: =SUM(L17)*200000/D17 -> #DIV/0! | O17: =SUM(H17,L17)*1000000/D17 -> #DIV/0! | Q17: =SUM(G17,H17,L17,P17)*200000/D17 -> #DIV/0! | V17: =SUM(T17)*1000000/E18 -> #DIV/0! | Y17: =SUM(T17,W17)*1000000/E17 -> #DIV/0! | AA17: =Z17*1000000/E17 -> #DIV/0! | AB17: =SUM(H17,T17)*1000000/F17 -> #DIV/0! | AC17: =SUM(H17,L17,T17,W17)*1000000/F17 -> #DIV/0! | AD17: =SUM(P17,Z17) -> 0
A18: 2022 | B18: May | F18: =D18+E18 -> 0 | J18: =H18*1000000/D18 -> #DIV/0! | K18: =H18*200000/D18 -> #DIV/0! | M18: =SUM(L18)*200000/D18 -> #DIV/0! | O18: =SUM(H18,L18)*1000000/D18 -> #DIV/0! | Q18: =SUM(G18,H18,L18,P18)*200000/D18 -> #DIV/0! | V18: =SUM(T18)*1000000/E19 -> #DIV/0! | Y18: =SUM(T18,W18)*1000000/E18 -> #DIV/0! | AA18: =Z18*1000000/E18 -> #DIV/0! | AB18: =SUM(H18,T18)*1000000/F18 -> #DIV/0! | AC18: =SUM(H18,L18,T18,W18)*1000000/F18 -> #DIV/0! | AD18: =SUM(P18,Z18) -> 0
A19: 2022 | B19: Jun | F19: =D19+E19 -> 0 | J19: =H19*1000000/D19 -> #DIV/0! | K19: =H19*200000/D19 -> #DIV/0! | M19: =SUM(L19)*200000/D19 -> #DIV/0! | O19: =SUM(H19,L19)*1000000/D19 -> #DIV/0! | Q19: =SUM(G19,H19,L19,P19)*200000/D19 -> #DIV/0! | V19: =SUM(T19)*1000000/E20 -> #DIV/0! | Y19: =SUM(T19,W19)*1000000/E19 -> #DIV/0! | AA19: =Z19*1000000/E19 -> #DIV/0! | AB19: =SUM(H19,T19)*1000000/F19 -> #DIV/0! | AC19: =SUM(H19,L19,T19,W19)*1000000/F19 -> #DIV/0! | AD19: =SUM(P19,Z19) -> 0
A20: 2022 | B20: Jul | F20: =D20+E20 -> 0 | J20: =H20*1000000/D20 -> #DIV/0! | K20: =H20*200000/D20 -> #DIV/0! | M20: =SUM(L20)*200000/D20 -> #DIV/0! | O20: =SUM(H20,L20)*1000000/D20 -> #DIV/0! | Q20: =SUM(G20,H20,L20,P20)*200000/D20 -> #DIV/0! | V20: =SUM(T20)*1000000/E21 -> #DIV/0! | Y20: =SUM(T20,W20)*1000000/E20 -> #DIV/0! | AA20: =Z20*1000000/E20 -> #DIV/0! | AB20: =SUM(H20,T20)*1000000/F20 -> #DIV/0! | AC20: =SUM(H20,L20,T20,W20)*1000000/F20 -> #DIV/0! | AD20: =SUM(P20,Z20) -> 0
A21: 2022 | B21: Aug | F21: =D21+E21 -> 0 | J21: =H21*1000000/D21 -> #DIV/0! | K21: =H21*200000/D21 -> #DIV/0! | M21: =SUM(L21)*200000/D21 -> #DIV/0! | O21: =SUM(H21,L21)*1000000/D21 -> #DIV/0! | Q21: =SUM(G21,H21,L21,P21)*200000/D21 -> #DIV/0! | V21: =SUM(T21)*1000000/E22 -> #DIV/0! | Y21: =SUM(T21,W21)*1000000/E21 -> #DIV/0! | AA21: =Z21*1000000/E21 -> #DIV/0! | AB21: =SUM(H21,T21)*1000000/F21 -> #DIV/0! | AC21: =SUM(H21,L21,T21,W21)*1000000/F21 -> #DIV/0! | AD21: =SUM(P21,Z21) -> 0
A22: 2022 | B22: Sep | F22: =D22+E22 -> 0 | J22: =H22*1000000/D22 -> #DIV/0! | K22: =H22*200000/D22 -> #DIV/0! | M22: =SUM(L22)*200000/D22 -> #DIV/0! | O22: =SUM(H22,L22)*1000000/D22 -> #DIV/0! | Q22: =SUM(G22,H22,L22,P22)*200000/D22 -> #DIV/0! | V22: =SUM(T22)*1000000/E23 -> #DIV/0! | Y22: =SUM(T22,W22)*1000000/E22 -> #DIV/0! | AA22: =Z22*1000000/E22 -> #DIV/0! | AB22: =SUM(H22,T22)*1000000/F22 -> #DIV/0! | AC22: =SUM(H22,L22,T22,W22)*1000000/F22 -> #DIV/0! | AD22: =SUM(P22,Z22) -> 0
A23: 2022 | B23: Oct | F23: =D23+E23 -> 0 | J23: =H23*1000000/D23 -> #DIV/0! | K23: =H23*200000/D23 -> #DIV/0! | M23: =SUM(L23)*200000/D23 -> #DIV/0! | O23: =SUM(H23,L23)*1000000/D23 -> #DIV/0! | Q23: =SUM(G23,H23,L23,P23)*200000/D23 -> #DIV/0! | V23: =SUM(T23)*1000000/E24 -> #DIV/0! | Y23: =SUM(T23,W23)*1000000/E23 -> #DIV/0! | AA23: =Z23*1000000/E23 -> #DIV/0! | AB23: =SUM(H23,T23)*1000000/F23 -> #DIV/0! | AC23: =SUM(H23,L23,T23,W23)*1000000/F23 -> #DIV/0! | AD23: =SUM(P23,Z23) -> 0
A24: 2022 | B24: Nov | F24: =D24+E24 -> 0 | J24: =H24*1000000/D24 -> #DIV/0! | K24: =H24*200000/D24 -> #DIV/0! | M24: =SUM(L24)*200000/D24 -> #DIV/0! | O24: =SUM(H24,L24)*1000000/D24 -> #DIV/0! | Q24: =SUM(G24,H24,L24,P24)*200000/D24 -> #DIV/0! | V24: =SUM(T24)*1000000/E25 -> #DIV/0! | Y24: =SUM(T24,W24)*1000000/E24 -> #DIV/0! | AA24: =Z24*1000000/E24 -> #DIV/0! | AB24: =SUM(H24,T24)*1000000/F24 -> #DIV/0! | AC24: =SUM(H24,L24,T24,W24)*1000000/F24 -> #DIV/0! | AD24: =SUM(P24,Z24) -> 0
A25: 2022 | B25: Dec | F25: =D25+E25 -> 0 | J25: =H25*1000000/D25 -> #DIV/0! | K25: =H25*200000/D25 -> #DIV/0! | M25: =SUM(L25)*200000/D25 -> #DIV/0! | O25: =SUM(H25,L25)*1000000/D25 -> #DIV/0! | Q25: =SUM(G25,H25,L25,P25)*200000/D25 -> #DIV/0! | V25: =SUM(T25)*1000000/E26 -> #VALUE! | Y25: =SUM(T25,W25)*1000000/E25 -> #DIV/0! | AA25: =Z25*1000000/E25 -> #DIV/0! | AB25: =SUM(H25,T25)*1000000/F25 -> #DIV/0! | AC25: =SUM(H25,L25,T25,W25)*1000000/F25 -> #DIV/0! | AD25: =SUM(P25,Z25) -> 0
A26: Totals / Averages | D26: AM/NS Manhours Manhours | E26: Contractor Manhours | F26: Combined Contractor & AM/NS Calvert MH | G26: Fatalities | H26: AM/NS Lost Time | I26: LWD/# of days away | J26: Global LTI + Employee) | K26: LTI Gobal | L26: AM/NS Restricted | M26: AM/NS Restricted Rate | N26: Restricted # of days | O26: LTI/LWCR (Employee) | P26: AM/NS Recordables | Q26: (RIR)Recordable Rate AM/NS | S26: Fatalities | T26: Contractor Lost time | U26: Contractor LWD/# of days away | V26: Global LTI (Contractor) | W26: Contractor Restricted | X26: Contractor Restricted # of days | Y26: Global LTI/LWCR (Contractor) | Z26: Contractor Recordables | AA26: (RIR)Recordable Rate Contractor | AB26: LTI (Employee + Contractor) | AC26: LTI + RWC (Employee + Contractor) | AD26: Employee / Contractor Recordables
A28: Dixie | G28: =SUM(G14:G25) -> 0 | K28: =SUM(H14:H25)*200000/#REF! -> #REF! | M28: =SUM(L14:L25)*200000/#REF! -> #REF! | O28: =SUM(H14:H25,L14:L25)*200000/#REF! -> #REF! | Q28: =SUM(G14:G25,H14:H25,L14:L25,P14:P25)*200000/#REF! -> #REF! | V28: =SUM(T14:T25)*200000/#REF! -> #REF!
B31: Month | D31: LWDC (SR) AM/NS | E31: LWDC (SR)Cont | F31: Restricted rate SR | G31: Restricted Rate SR Contractors | H31: First Aid Cases | I31: First Aid Frequency Rate | J31: Property Damage | K31: PDR | L31: Near Miss | M31: AM/NS
A32: 2021 | B32: Jan | D32: =I2*1000/D2 -> #DIV/0! | E32: =SUM(U2)*1000/F2 -> #DIV/0! | I32: =SUM(H32)*1000000/D2 -> #DIV/0! | K32: =SUM(J32)*1000000/E2 -> #DIV/0! | M32: =SUM(L32)*1000000/D2 -> #DIV/0!
A33: 2021 | B33: Feb | D33: =I3*1000/D3 -> #DIV/0! | E33: =SUM(U3)*1000/F3 -> #DIV/0! | I33: =SUM(H33)*1000000/D3 -> #DIV/0! | K33: =SUM(J33)*1000000/E3 -> #DIV/0! | M33: =SUM(L33)*1000000/D3 -> #DIV/0!
A34: 2021 | B34: Mar | D34: =I4*1000/D4 -> #DIV/0! | E34: =SUM(U4)*1000/F4 -> #DIV/0! | I34: =SUM(H34)*1000000/D4 -> #DIV/0! | K34: =SUM(J34)*1000000/E4 -> #DIV/0! | M34: =SUM(L34)*1000000/D4 -> #DIV/0!
A35: 2021 | B35: Apr | D35: =I5*1000/D5 -> #DIV/0! | E35: =SUM(U5)*1000/F5 -> #DIV/0! | I35: =SUM(H35)*1000000/D5 -> #DIV/0! | K35: =SUM(J35)*1000000/E5 -> #DIV/0! | M35: =SUM(L35)*1000000/D5 -> #DIV/0!
A36: 2021 | B36: May | D36: =I6*1000/D6 -> #DIV/0! | E36: =SUM(U6)*1000/F6 -> #DIV/0! | I36: =SUM(H36)*1000000/D6 -> #DIV/0! | K36: =SUM(J36)*1000000/E6 -> #DIV/0! | M36: =SUM(L36)*1000000/D6 -> #DIV/0!
A37: 2021 | B37: Jun | D37: =I7*1000/D7 -> #DIV/0! | E37: =SUM(U7)*1000/F7 -> #DIV/0! | I37: =SUM(H37)*1000000/D7 -> #DIV/0! | K37: =SUM(J37)*1000000/E7 -> #DIV/0! | M37: =SUM(L37)*1000000/D7 -> #DIV/0!
A38: 2021 | B38: Jul | D38: =I8*1000/D8 -> #DIV/0! | E38: =SUM(U8)*1000/F8 -> #DIV/0! | I38: =SUM(H38)*1000000/D8 -> #DIV/0! | K38: =SUM(J38)*1000000/E8 -> #DIV/0! | M38: =SUM(L38)*1000000/D8 -> #DIV/0!
A39: 2021 | B39: Aug | D39: =I9*1000/D9 -> #DIV/0! | E39: =SUM(U9)*1000/F9 -> #DIV/0! | I39: =SUM(H39)*1000000/D9 -> #DIV/0! | K39: =SUM(J39)*1000000/E9 -> #DIV/0! | M39: =SUM(L39)*1000000/D9 -> #DIV/0!
A40: 2021 | B40: Sep | D40: =I10*1000/D10 -> #DIV/0! | E40: =SUM(U10)*1000/F10 -> #DIV/0! | I40: =SUM(H40)*1000000/D10 -> #DIV/0! | K40: =SUM(J40)*1000000/E10 -> #DIV/0! | M40: =SUM(L40)*1000000/D10 -> #DIV/0!
A41: 2021 | B41: Oct | D41: =I11*1000/D11 -> #DIV/0! | E41: =SUM(U11)*1000/F11 -> #DIV/0! | I41: =SUM(H41)*1000000/D11 -> #DIV/0! | K41: =SUM(J41)*1000000/E11 -> #DIV/0! | M41: =SUM(L41)*1000000/D11 -> #DIV/0!
A42: 2021 | B42: Nov | D42: =I12*1000/D12 -> #DIV/0! | E42: =SUM(U12)*1000/F12 -> #DIV/0! | I42: =SUM(H42)*1000000/D12 -> #DIV/0! | K42: =SUM(J42)*1000000/E12 -> #DIV/0! | M42: =SUM(L42)*1000000/D12 -> #DIV/0!
A43: 2021 | B43: Dec | D43: =I13*1000/D13 -> #DIV/0! | E43: =SUM(U13)*1000/F13 -> #DIV/0! | I43: =SUM(H43)*1000000/D13 -> #DIV/0! | K43: =SUM(J43)*1000000/E13 -> #DIV/0! | M43: =SUM(L43)*1000000/D13 -> #DIV/0!
...

Sheet ENV 

Sheet Safety Observation Dash
A1: Safety Observation Contact Process Indicators

Sheet SSO-Site -25 
A1: Safety Observation Contact
B3: 2025-0301 | AL3: Safe Act / Condition | AO3: Unsafe Act/ Condition
B4: Safe Act / Condition | F4: Jan | G4: Feb | H4: Mar | I4: Apr | J4: May | K4: Jun | L4: Jul | M4: Aug | N4: Sep | O4: Oct | P4: Nov | Q4: Dec | R4: Total YTD | T4: Unsafe Act/ Condition | X4: Jan | Y4: Feb | Z4: Mar | AA4: Apr | AB4: May | AC4: Jun | AD4: Jul | AE4: Aug | AF4: Sep | AG4: Oct | AH4: Nov | AI4: Dec | AJ4: Total YTD | AL4: Material handling or lifiting | AM4: 4 | AO4: Forklift | AP4: 6
B5: Building | H5: 1 | R5: =SUM(F5:Q5) -> 1 | T5: Building | X5: 3 | Y5: 2 | AA5: 4 | AB5: 2 | AJ5: =SUM(X5:AI5) -> 11 | AL5: Forklift | AM5: 2 | AO5: Tools & Equipment | AP5: 6
B6: Chemical | R6: =SUM(F6:Q6) -> 0 | T6: Chemical | Z6: 1 | AA6: 1 | AJ6: =SUM(X6:AI6) -> 2 | AL6: PPE | AM6: 2 | AO6: Building | AP6: 5
B7: Confined Space | R7: =SUM(F7:Q7) -> 0 | T7: Confined Space | AJ7: =SUM(X7:AI7) -> 0 | AL7: Housekeepng | AM7: 1 | AO7: Housekeepng | AP7: 3
B8: Electrical | R8: =SUM(F8:Q8) -> 0 | T8: Electrical | Z8: 1 | AA8: 3 | AB8: 1 | AJ8: =SUM(X8:AI8) -> 5 | AL8: Building | AM8: 0 | AO8: PPE | AP8: 3
B9: Ergonomics | R9: =SUM(F9:Q9) -> 0 | T9: Ergonomics | AJ9: =SUM(X9:AI9) -> 0 | AL9: Chemical | AM9: 0 | AO9: Walking working surface | AP9: 2
B10: Fire | R10: =SUM(F10:Q10) -> 0 | T10: Fire system | AA10: 1 | AB10: 1 | AJ10: =SUM(X10:AI10) -> 2 | AL10: Confined Space | AM10: 0 | AO10: Work at elevation | AP10: 2
B11: Forklift | G11: 2 | H11: 4 | I11: 3 | J11: 1 | R11: =SUM(F11:Q11) -> 10 | T11: Forklift | X11: 2 | Y11: 4 | Z11: 1 | AJ11: =SUM(X11:AI11) -> 7 | AL11: Electrical | AM11: 0 | AO11: LOTO | AP11: 1
B12: Housekeepng | G12: 1 | H12: 4 | I12: 3 | R12: =SUM(F12:Q12) -> 8 | T12: Housekeepng | X12: 2 | Y12: 1 | Z12: 2 | AA12: 2 | AB12: 2 | AJ12: =SUM(X12:AI12) -> 9 | AL12: Ergonomics | AM12: 0 | AO12: Chemical | AP12: 0
B13: LOTO | R13: =SUM(F13:Q13) -> 0 | T13: LOTO | X13: 1 | AJ13: =SUM(X13:AI13) -> 1 | AL13: Fire | AM13: 0 | AO13: Confined Space | AP13: 0
B14: Material defect | R14: =SUM(F14:Q14) -> 0 | T14: Material defect | Z14: 1 | AA14: 2 | AB14: 2 | AJ14: =SUM(X14:AI14) -> 5 | AL14: LOTO | AM14: 0 | AO14: Electrical | AP14: 0
B15: Material handling or lifiting | F15: 2 | G15: 2 | J15: 1 | R15: =SUM(F15:Q15) -> 5 | T15: Material handling or lifiting | AJ15: =SUM(X15:AI15) -> 0 | AL15: Material defect | AM15: 0 | AO15: Ergonomics | AP15: 0
B16: Non work related | R16: =SUM(F16:Q16) -> 0 | T16: Non work related | AJ16: =SUM(X16:AI16) -> 0 | AL16: Non work related | AM16: 0 | AO16: Fire | AP16: 0
B17: PPE | G17: 2 | H17: 1 | I17: 4 | J17: 5 | R17: =SUM(F17:Q17) -> 12 | T17: PPE | X17: 1 | Y17: 2 | Z17: 1 | AJ17: =SUM(X17:AI17) -> 4 | AL17: Respiratory protection | AM17: 0 | AO17: Material defect | AP17: 0
B18: Respiratory protection | R18: =SUM(F18:Q18) -> 0 | T18: Respiratory protection | AJ18: =SUM(X18:AI18) -> 0 | AL18: Slip, trip, fall | AM18: 0 | AO18: Material handling or lifiting | AP18: 0
B19: Slip, trip, fall | R19: =SUM(F19:Q19) -> 0 | T19: Slip, trip, fall | Z19: 2 | AA19: 3 | AB19: 1 | AJ19: =SUM(X19:AI19) -> 6 | AL19: Stairs, ladders | AM19: 0 | AO19: Non work related | AP19: 0
B20: Stairs, ladders | R20: =SUM(F20:Q20) -> 0 | T20: Stairs, ladders | AB20: 1 | AJ20: =SUM(X20:AI20) -> 1 | AL20: Tools | AM20: 0 | AO20: Respiratory protection | AP20: 0
B21: Tools & Equipment | R21: =SUM(F21:Q21) -> 0 | T21: Tools & Equipment | X21: 1 | Y21: 5 | Z21: 1 | AA21: 2 | AJ21: =SUM(X21:AI21) -> 9 | AL21: Vehicle company owned | AM21: 0 | AO21: Slip, trip, fall | AP21: 0
B22: Vehicle company owned | R22: =SUM(F22:Q22) -> 0 | T22: Vehicle company owned | AJ22: =SUM(X22:AI22) -> 0 | AL22: Vehicle not company owned | AM22: 0 | AO22: Stairs, ladders | AP22: 0
B23: Vehicle not company owned | R23: =SUM(F23:Q23) -> 0 | T23: Vehicle not company owned | AJ23: =SUM(X23:AI23) -> 0 | AL23: Walking working surface | AM23: 0 | AO23: Vehicle company owned | AP23: 0
B24: Walking working surface | H24: 1 | J24: 1 | R24: =SUM(F24:Q24) -> 2 | T24: Walking working surface | Y24: 2 | AB24: 3 | AJ24: =SUM(X24:AI24) -> 5 | AL24: Work at elevation | AM24: 0 | AO24: Vehicle not company owned | AP24: 0
B25: Work at elevation | R25: =SUM(F25:Q25) -> 0 | T25: Work at elevation | X25: 1 | Y25: 1 | AJ25: =SUM(X25:AI25) -> 2
B26: Crane | R26: =SUM(F26:Q26) -> 0 | T26: Crane | AJ26: =SUM(X26:AI26) -> 0
R27: =SUM(F27:Q27) -> 0 | AJ27: =SUM(X27:AI27) -> 0
R28: =SUM(F28:Q28) -> 0 | AJ28: =SUM(X28:AI28) -> 0
R29: =SUM(F29:Q29) -> 0 | AJ29: =SUM(X29:AI29) -> 0
R30: =SUM(F30:Q30) -> 0 | AJ30: =SUM(X30:AI30) -> 0
R31: =SUM(F31:Q31) -> 0 | AJ31: =SUM(X31:AI31) -> 0
R32: =SUM(F32:Q32) -> 0 | AJ32: =SUM(X32:AI32) -> 0
R33: =SUM(F33:Q33) -> 0 | AJ33: =SUM(X33:AI33) -> 0
R36: TOTOYTD | AJ36: TOTOYTD
E37: Total MTD | F37: =SUM(F5:F33) -> 2 | G37: =SUM(G5:G33) -> 7 | H37: =SUM(H5:H33) -> 11 | I37: =SUM(I5:I33) -> 10 | J37: =SUM(J5:J33) -> 8 | K37: =SUM(K5:K33) -> 0 | L37: =SUM(L5:L33) -> 0 | M37: =SUM(M5:M33) -> 0 | ... R37: =SUM(R5:R33) -> 38 | W37: Total MTD | X37: =SUM(X5:X33) -> 11 | Y37: =SUM(Y5:Y33) -> 17 | Z37: =SUM(Z5:Z33) -> 10 | AA37: =SUM(AA5:AA33) -> 18 | AB37: =SUM(AB5:AB33) -> 13 | AC37: =SUM(AC5:AC33) -> 0 | AD37: =SUM(AD5:AD33) -> 0 | AE37: =SUM(AE5:AE33) -> 0 | ... AJ37: =SUM(AJ5:AJ33) -> 69
F39: Jan | G39: Feb | H39: Mar | I39: Apr | J39: May | K39: Jun | L39: Jul | M39: Aug | N39: Sep | O39: Oct | P39: Nov | Q39: Dec | R39: Total | U39: Total Observations | V39: JAN | W39: FEB | X39: MAR | Y39: APR | Z39: MAY | AA39: JUN | AB39: JUL | AC39: AUG | AD39: SEP | AE39: OCT | AF39: NOV | AG39: DEC
D40: Safe Act | F40: 1 | G40: 6 | H40: 8 | I40: 7 | J40: 7 | R40: =SUM(F40:Q40) -> 29 | V40: =SUM(F37,X37) -> 13 | W40: =SUM(G37,Y37) -> 24 | X40: 20 | Y40: 20 | Z40: 22
D41: Safe Condition | F41: 1 | G41: 2 | H41: 1 | I41: 3 | J41: 1 | R41: =SUM(F41:Q41) -> 8 | S41: =SUM(R40,R41) -> 37
D42: Unsafe Act | F42: 4 | G42: 5 | H42: 2 | I42: 1 | J42: 0 | R42: =SUM(F42:Q42) -> 12
D43: Unsafe Condition | F43: 7 | G43: 19 | H43: 9 | I43: 18 | J43: 14 | R43: =SUM(F43:Q43) -> 67 | S43: =SUM(R42,R43) -> 79
P44: =SUM(P40:P43) -> 0 | R44: =SUM(R40:R43) -> 116
...

Sheet PPT Work
A1: Safe Act | C1: ='SSO-Site -25 '!R40 -> 29
A2: Safe Condition | C2: ='SSO-Site -25 '!R41 -> 8
A3: Unsafe Act | C3: ='SSO-Site -25 '!R42 -> 12
A4: Unsafe Condition | C4: ='SSO-Site -25 '!R43 -> 67
C5: =SUM(C1:C4) -> 116
A16: Observation
C17: Jan | D17: Feb | E17: Mar | F17: Apr | G17: May | H17: Jun | I17: Jul | J17: Aug | K17: Sep | L17: Oct | M17: Nov | N17: Dec | O17: Total
A18: Safe Act | C18: {='SSO-Site -25 '!F40:F43} -> 1 | D18: {='SSO-Site -25 '!G40:G43} -> 6 | E18: 8 | F18: 7 | G18: 7 | O18: =SUM(C18:N18) -> 29
A19: Safe Condition | C19: 1 | D19: 2 | E19: 1 | F19: 3 | G19: 1 | O19: =SUM(C19:N19) -> 8 | P19: =SUM(O18,O19) -> 37
A20: Unsafe Act | C20: 4 | D20: 5 | E20: 2 | F20: 1 | G20: 0 | O20: =SUM(C20:N20) -> 12
A21: Unsafe Condition | C21: 7 | D21: 19 | E21: 9 | F21: 18 | G21: 14 | O21: =SUM(C21:N21) -> 67 | P21: =SUM(O20,O21) -> 79
A23: Accumulating Condition / Act
C24: Jan | D24: Feb | E24: Mar | F24: Apr | G24: May | H24: Jun | I24: Jul | J24: Aug | K24: Sep | L24: Oct | M24: Nov | N24: Dec
A25: Safe Observation | C25: 2 | D25: 10 | E25: 19 | F25: 29 | G25: 37
A26: Unsafe Observation | C26: 11 | D26: 35 | E26: 46 | F26: 65 | G26: 79
A43: Unsafe Observation
E44: Jan | F44: Feb | G44: Mar | H44: Apr | I44: May | J44: Jun | K44: Jul | L44: Aug | M44: Sep | N44: Oct | O44: Nov | P44: Dec
A45: Building | E45: 3 | F45: 2 | H45: 4 | I45: 2
A46: Chemical | G46: 1 | H46: 1
A47: Confined Space
A48: Electrical | G48: 1 | H48: 3 | I48: 1
A49: Ergonomics
A50: Fire | H50: 1 | I50: 1
A51: Forklift | E51: 2 | F51: 4 | G51: 1
A52: Housekeepng | E52: 2 | F52: 1 | G52: 2 | H52: 2 | I52: 2
A53: LOTO
A54: Material defect | G54: 1 | H54: 2 | I54: 2
A55: Material handling or lifiting
A56: Non work related
A57: PPE | F57: 2 | G57: 1
A58: Respiratory protection | E58: 1
A59: Slip, trip, fall | G59: 2 | H59: 3 | I59: 1
A60: Stairs, ladders | I60: 1
A61: Tools | E61: 1 | F61: 5 | G61: 1 | H61: 2
A62: Vehicle company owned
A63: Vehicle not company owned
A64: Walking working surface | F64: 2 | I64: 3
A65: Work at elevation | E65: 1 | F65: 1
A70: Safe Observsation
E71: Jan | F71: Feb | G71: Mar | H71: Apr | I71: May | J71: Jun | K71: Jul | L71: Aug | M71: Sep | N71: Oct | O71: Nov | P71: Dec
...

Sheet TRIR EXP.
H7: 2021 | I7: 2022 | J7: 2023 | K7: 2024 | L7: 2025 | M7: 2026
G8: Recordable | H8: 1 | I8: 3 | J8: 1 | K8: 1 | L8: 0 | M8: 1
G9: Incident | L9: 41 | M9: ='Incident Data'!N7 -> 41
G15: Man Hours | H15: 172301 | I15: 176350 | J15: 168563 | K15: 174706 | L15: 191751 | M15: =Rates!M42 -> 145194
G17: TIR | L17: =L9*200000/L15 -> 42.763793 | M17: =M9*200000/M15 -> 56.476163
G18: LCY TRIR | H18: 1.16 | I18: 3.4 | J18: 1.19 | K18: 1.14 | L18: =L8*200000/L15 -> 0 | M18: =M8*200000/M15 -> 1.3774674
G19: Bureau of labor Statistics industry avg. | H19: 2.7 | I19: 1.9 | J19: 1.9 | K19: 1.9 | L19: 1.9 | M19: 1.9

Sheet Sheet2
